// 45: Handling multiple errors with "Result" in Rust

fn main() {
    // ...
}
